<?xml version="1.0" encoding="utf-8"?>
<!-- This URDF was automatically created by SolidWorks to URDF Exporter! Originally created by Stephen Brawner (brawner@gmail.com) 
     Commit Version: 1.6.0-4-g7f85cfe  Build Version: 1.6.7995.38578
     For more information, please see http://wiki.ros.org/sw_urdf_exporter -->

      

<robot xmlns:xacro="http://www.ros.org/wiki/xacro" name="sabry">

   <link name="world"/>
  <xacro:include filename="$(find sabry)/urdf/tools.xacro"/>
  <xacro:include filename="$(find sabry)/urdf/tools_station.xacro"/>

  <xacro:arg name="is_ignition" default="false"/>
  <xacro:if value="$(arg is_ignition)">
  <xacro:include filename="$(find sabry)/urdf/sabry_gazebo.xacro" />

        <!-- Include ros2_control Plugins -->
  <xacro:include filename="$(find sabry)/urdf/sabry_controllers.xacro" />
  </xacro:if>
  <xacro:property name="effort" value="15.0" />
 


  <link
    name="base_link">
    <inertial>
      <origin
        xyz="-0.0179134665346439 0.000764499107738575 0.0905227445399475"
        rpy="0 0 0" />
      <mass
        value="1.82511281813038" />
      <inertia
        ixx="0.00909711907031737"
        ixy="-5.34667830042109E-05"
        ixz="0.000697294525050743"
        iyy="0.0166356638599367"
        iyz="4.84901188619488E-05"
        izz="0.0105645854595607" />
    </inertial>
    <visual>
      <origin
        xyz="0 0 0"
        rpy="0 0 0" />
      <geometry>
        <mesh
          filename="package://sabry/meshes/base_link.STL" />
      </geometry>
      <material
        name="">
        <color
          rgba="0.698039215686274 0.698039215686274 0.698039215686274 1" />
      </material>
    </visual>
    <collision>
      <origin
        xyz="0 0 0"
        rpy="0 0 0" />
      <geometry>
        <mesh
          filename="package://sabry/meshes/base_link.STL" />
      </geometry>
    </collision>
  </link>
  <joint name="virtual_joint" type="fixed">
        <parent link="world"/>
        <child link="base_link"/>
        <origin xyz="0 0 0" rpy="0 0 0"/>
    </joint> 
  <link
    name="waist_Link">
    <inertial>
      <origin
        xyz="9.18719391358189E-05 0.00101463218390656 0.0570433025547262"
        rpy="0 0 0" />
      <mass
        value="0.737001248359429" />
      <inertia
        ixx="0.0010068681071999"
        ixy="1.1846823795479E-08"
        ixz="-1.25918132464241E-06"
        iyy="0.00121535979702413"
        iyz="-1.72681357987945E-06"
        izz="0.000820031339261215" />
    </inertial>
    <visual>
      <origin
        xyz="0 0 0"
        rpy="0 0 0" />
      <geometry>
        <mesh
          filename="package://sabry/meshes/waist_Link.STL" />
      </geometry>
      <material
        name="">
        <color
          rgba="0.698039215686274 0.698039215686274 0.698039215686274 1" />
      </material>
    </visual>
    <collision>
      <origin
        xyz="0 0 0"
        rpy="0 0 0" />
      <geometry>
        <mesh
          filename="package://sabry/meshes/waist_Link.STL" />
      </geometry>
    </collision>
  </link>
  <joint
    name="waist_joint"
    type="revolute">
    <origin
      xyz="0 0 0.178"
      rpy="0 0 0" />
    <parent
      link="base_link" />
    <child
      link="waist_Link" />
    <axis
      xyz="0 0 -1" />
    <limit
      lower="-3.14"
      upper="3.14"
       effort="${effort}"
      velocity="1" />
  </joint>
  <link
    name="upperarm_Link">
    <inertial>
      <origin
        xyz="-0.0210207105880525 0.0871863218413688 -0.0506536830754468"
        rpy="0 0 0" />
      <mass
        value="0.587031804351146" />
      <inertia
        ixx="0.00363274282332789"
        ixy="0.000126099601392782"
        ixz="-1.44710547902184E-05"
        iyy="0.000945789905678025"
        iyz="2.05096681996651E-05"
        izz="0.00380076631192487" />
    </inertial>
    <visual>
      <origin
        xyz="0 0 0"
        rpy="0 0 0" />
      <geometry>
        <mesh
          filename="package://sabry/meshes/upperarm_Link.STL" />
      </geometry>
      <material
        name="">
        <color
          rgba="0.698039215686274 0.698039215686274 0.698039215686274 1" />
      </material>
    </visual>
    <collision>
      <origin
        xyz="0 0 0"
        rpy="0 0 0" />
      <geometry>
        <mesh
          filename="package://sabry/meshes/upperarm_Link.STL" />
      </geometry>
    </collision>
  </link>
  <joint
    name="upperarm_joint"
    type="revolute">
    <origin
      xyz="0 -0.0599999999999987 0.081999999999997"
      rpy="1.5707963267949 0 0" />
    <parent
      link="waist_Link" />
    <child
      link="upperarm_Link" />
    <axis
      xyz="0 0 -1" />
    <limit
      lower="-1.57"
      upper="1.57"
      effort="${effort}"
      velocity="1" />
  </joint>
  <link
    name="lowerarm_Link">
    <inertial>
      <origin
        xyz="-8.1406683731855E-05 -0.0972489916787859 -0.0624594061117589"
        rpy="0 0 0" />
      <mass
        value="0.50077148235924" />
      <inertia
        ixx="0.00217963221773672"
        ixy="4.00108854768121E-06"
        ixz="2.09001241516257E-08"
        iyy="0.000387783886168588"
        iyz="4.84330089571311E-06"
        izz="0.00237953876094112" />
    </inertial>
    <visual>
      <origin
        xyz="0 0 0"
        rpy="0 0 0" />
      <geometry>
        <mesh
          filename="package://sabry/meshes/lowerarm_Link.STL" />
      </geometry>
      <material
        name="">
        <color
          rgba="0.698039215686274 0.698039215686274 0.698039215686274 1" />
      </material>
    </visual>
    <collision>
      <origin
        xyz="0 0 0"
        rpy="0 0 0" />
      <geometry>
        <mesh
          filename="package://sabry/meshes/lowerarm_Link.STL" />
      </geometry>
    </collision>
  </link>
  <joint
    name="lowerarm_joint"
    type="revolute">
    <origin
      xyz="0 0.200000000000004 0"
      rpy="0 0 1.5707963267949" />
    <parent
      link="upperarm_Link" />
    <child
      link="lowerarm_Link" />
    <axis
      xyz="0 0 -1" />
    <limit
      lower="-1.57"
      upper="1.57"
       effort="${effort}"
      velocity="1" />
  </joint>
  <link
    name="wrist_pitch_Link">
    <inertial>
      <origin
        xyz="-6.14774114847949E-05 -0.00253319340524844 -0.0241831322546577"
        rpy="0 0 0" />
      <mass
        value="0.114901736160438" />
      <inertia
        ixx="3.5581969638824E-05"
        ixy="-1.14316930570037E-08"
        ixz="-3.77155460231747E-09"
        iyy="3.89196461594281E-05"
        iyz="-6.06354142804142E-08"
        izz="3.85696719910037E-05" />
    </inertial>
    <visual>
      <origin
        xyz="0 0 0"
        rpy="0 0 0" />
      <geometry>
        <mesh
          filename="package://sabry/meshes/wrist_pitch_Link.STL" />
      </geometry>
      <material
        name="">
        <color
          rgba="0.698039215686274 0.698039215686274 0.698039215686274 1" />
      </material>
    </visual>
    <collision>
      <origin
        xyz="0 0 0"
        rpy="0 0 0" />
      <geometry>
        <mesh
          filename="package://sabry/meshes/wrist_pitch_Link.STL" />
      </geometry>
    </collision>
  </link>
  <joint
    name="wrist_pitch_joint"
    type="revolute">
    <origin
      xyz="0 -0.2 -0.0358"
      rpy="0 0 -1.5708" />
    <parent
      link="lowerarm_Link" />
    <child
      link="wrist_pitch_Link" />
    <axis
      xyz="0 0 1" />
    <limit
      lower="-1.57"
      upper="1.57"
       effort="${effort}"
      velocity="1" />
  </joint>
  <link
    name="wrist_yaw_Link">
    <inertial>
      <origin
        xyz="-0.000359348115456209 -4.13354832094904E-08 0.0122032256779013"
        rpy="0 0 0" />
      <mass
        value="0.0695856017781036" />
      <inertia
        ixx="2.77505510624076E-05"
        ixy="3.82039604837932E-12"
        ixz="-2.23085070530585E-07"
        iyy="2.66626967956507E-05"
        iyz="1.89046012150345E-11"
        izz="4.34359279474784E-05" />
    </inertial>
    <visual>
      <origin
        xyz="0 0 0"
        rpy="0 0 0" />
      <geometry>
        <mesh
          filename="package://sabry/meshes/wrist_yaw_Link.STL" />
      </geometry>
      <material
        name="">
        <color
          rgba="0.698039215686274 0.698039215686274 0.698039215686274 1" />
      </material>
    </visual>
    <collision>
      <origin
        xyz="0 0 0"
        rpy="0 0 0" />
      <geometry>
        <mesh
          filename="package://sabry/meshes/wrist_yaw_Link.STL" />
      </geometry>
    </collision>
  </link>
  <joint
    name="wrist_yaw_joint"
    type="revolute">
    <origin
      xyz="-1.7692E-05 -0.0318 -0.0242"
      rpy="1.5708 0 0" />
    <parent
      link="wrist_pitch_Link" />
    <child
      link="wrist_yaw_Link" />
    <axis
      xyz="0 0 1" />
    <limit
      lower="0"
      upper="6.28"
       effort="${effort}"
      velocity="1" />
  </joint>

  <!-- Tool mounting interface (where tools attach) -->
  <link name="tool_mount_link">
    <inertial>
      <mass value="0.01"/>
      <inertia ixx="1e-6" ixy="0" ixz="0" iyy="1e-6" iyz="0" izz="1e-6"/>
    </inertial>
  </link>

  <joint name="tool_mount" type="fixed">
    <parent link="wrist_yaw_Link"/>
    <child link="tool_mount_link"/>
    <origin xyz="0 0 0.03" rpy="0 0 0"/>
  </joint>

</robot>